## async、await是Promise的一个语法糖:

**我们可以将await关键字后面执行的代码，看做是包裹在(resolve，reject)=>{函数执行}中的代码;**
**await的下一条语句，可以看做是then(res =>{函数执行})中的代码;**

## async函数

* 函数的返回值为promise对象
* promise对象的结果由async.函数执行的返回值决定

```js
async function one() {
    //函数类部没有调用，则返回的是没有结果的promise对象
  }
  console.log(one());
  /*
    [[PromiseState]]: "fulfilled"
    [[PromiseResult]]: undefined
  */

async function foo() {
    // 只返回一个值，并不是promise，结果为reject的promise，result为1。
      return 1;
    }
console.log(foo());
/*
	[[PromiseState]]: "fulfilled"
	[[PromiseResult]]: 1
*/

 async function two() {
    return new Promise((resolve, reject) => {
      resolve('ok');
    })
  }
  console.log(two());
  /* 
    [[PromiseState]]: "fulfilled"
    [[PromiseResult]]: "ok"
  */

  async function three() {
    return new Promise((resolve, reject) => {
      reject('error');
    })
  }
  console.log(three());
  /*
    [[PromiseState]]: "rejected"
    [[PromiseResult]]: "error"
  */

  async function four() {
    return new Promise((resolve, reject) => {
      throw ("ERROR")
    })
  }
  console.log(four());
  /*
    [[PromiseState]]: "rejected"
    [[PromiseResult]]: "ERROR"
  */
```

## await

* await右侧的表达式一般为promise对象，但也可以是其它的值
* 如果表达式是promise对象, **await返回的是promise成功的值**
* 如果表达式是其它值，直接将此值作为await 的返回值

#### 关于await的执行顺序问题

其实就类似于生活中的`排队`，咱们生活中排队买东西，肯定是要上一个人买完，才轮到下一个人。而上面也一样，在`async`函数中，`await`规定了异步操作只能一个一个排队执行，从而达到**用同步方式，执行异步操作**的效果。

```js
//这个例子await后面都是跟着异步操作Promise
function request(num) { // 模拟接口请求
  return new Promise(resolve => {
    setTimeout(() => {
      resolve(num * 2)
    }, 1000)
  })
}

async function fn () {
  const res1 = await request(5)
  const res2 = await request(res1)
  console.log(res2) // 2秒后输出 20
}

fn();
```

```js
//如果不接Promise会怎么样呢？
function request(num) { // 去掉Promise
  setTimeout(() => {
    console.log(num * 2)
  }, 1000)
}

async function fn() {
  await request(1) // 2
  await request(2) // 4
  // 1秒后执行完  同时输出
}
fn()
//可以看出，如果await后面接的不是Promise的话，其实是达不到排队的效果的
```



**注意：**

* await必须写在async函数中，但 async函数中可以没有await
* 如果await 的 promise失败了，就会抛出异常，需要通过try...catch捕获处理

```js
    async function fun() {
      try {
        await new Promise((resolve, reject) => {
          reject('error')
        })
      } catch (e) {
        console.log(e);
      }
    }
    fun();//error
```

**面试题**

```js
  function testSometing() {
    console.log("testSomething");
    return "return testSomething";
  }

  async function testAsync() {
    console.log("testAsync");
    return Promise.resolve("hello async");
  }

  async function test() {
    console.log("test start...");

    const testFn1 = await testSometing();
    console.log(testFn1);

    const testFn2 = await testAsync();
    console.log(testFn2);

    console.log('test end...');
  }

  test();

  var promiseFn = new Promise((resolve) => {
    console.log("promise START...");
    resolve("promise RESOLVE");
  });
  promiseFn.then((val) => console.log(val));

  console.log("===END===");

//结果：可以参考Node.js中游览器事件队列中的执行步骤
/*
test start...
testSomething
promise START...
===END===
return testSomething
testAsync
promise RESOLVE
hello async
test end...
*/
```



## 总结：

async与await就是替代了Promise.then方法的回调，简化了操作，可以直接得到结果